Workbook

Sheet Domingo - Jueves
D1: Inicio horario mañana/continuo | E1: Fin horario mañana/continuo | F1: Inicio horario tarde | G1: Fin horario tarde
B2: Para formatos de HD continuos poner el siguiente formato: | D2: 0.5 | E2: 0.020833333
B3: Para formatos de HD con entreturno poner el siguiente formato: | D3: 0.5 | E3: 0.66666667 | F3: 0.79166667 | G3: 0
D7: Introduce el codigo BK
A8: GA | B8: GZ | C8: RESTAURANTE | D8: RESTAURANTE | E8: Inicio horario mañana/continuo | F8: Fin horario mañana/continuo | G8: Inicio horario tarde | H8: Fin horario tarde
A9: Salvador Pujol | B9: Jose Luis Galiana | C9: PLK Justicia (Lunes-jueves) | D9: 13884 | E9: 0.5 | F9: 0.041666667
A10: Salvador Pujol | B10: Jose Luis Galiana | C10: PLK Justicia (Domingo) | D10: 13884 | E10: 0.5 | F10: 0.041666667
A11: Salvador Pujol | B11: Jose Luis Galiana | C11: PLK Juan de Borbon (Lunes-jueves) | D11: 14853 | E11: 0.52083333 | F11: 0
A12: Salvador Pujol | B12: Jose Luis Galiana | C12: PLK Juan de Borbon (Domingo) | D12: 14853 | E12: 0.5 | F12: 0.020833333
A13: Salvador Pujol | B13: Jose Luis Galiana | C13: PLK Aguilas (Lunes-jueves) | D13: 15110 | E13: 0.5 | F13: 0
A14: Salvador Pujol | B14: Jose Luis Galiana | C14: PLK Aguilas (Domingo) | D14: 15110 | E14: 0.5 | F14: 0.041666667
A15: Salvador Pujol | B15: Jose Luis Galiana | C15: PLK Molina de segura (Lunes-jueves) | D15: 14920 | E15: 0.52083333 | F15: 0.020833333
A16: Salvador Pujol | B16: Jose Luis Galiana | C16: PLK Molina de segura (Domingo) | D16: 14920 | E16: 0.52083333 | F16: 0.020833333
A17: Salvador Pujol | B17: Jose Luis Galiana | C17: PLK Traperia (Lunes-jueves) | D17: 15223 | E17: 0.5 | F17: 0
A18: Salvador Pujol | B18: Jose Luis Galiana | C18: PLK Traperia (Domingo) | D18: 15223 | E18: 0.5 | F18: 0
A19: Salvador Pujol | B19: Jose Luis Galiana | C19: PLK Sangonera (Lunes-jueves) | D19: 13674 | E19: 0.52083333 | F19: 0
A20: Salvador Pujol | B20: Jose Luis Galiana | C20: PLK Sangonera (Domingo) | D20: 13674 | E20: 0.5 | F20: 0.020833333
... A24: Salvador Pujol | B24: Vanesa Martinez | C24: Plk Torrevieja | D24: 15261 | E24: 0.4375 | F24: 0.125
A25: Salvador Pujol | B25: Vanesa Martinez | C25: Plk Dos Mares | D25: 14123 | E25: 0.47916667 | F25: 0.66666667 | G25: 0.79166667 | H25: 0
A26: Salvador Pujol | B26: Vanesa Martinez | C26: Plk Cartagena | D26: 13696 | E26: 0.47916667 | F26: 0.66666667 | G26: 0.79166667 | H26: 0
A27: Salvador Pujol | B27: Raul de Dios | C27: PLK Vistahermosa (DOMINGO) | D27: 14519 | E27: 0.5 | F27: 0.083333333
A28: Salvador Pujol | B28: Raul de Dios | C28: PLK Vistahermosa (Lunes-jueves) | D28: 14519 | E28: 0.5 | F28: 0.041666667
A29: Salvador Pujol | B29: Raul de Dios | C29: PLK San Juan | D29: 14768 | E29: 0.5 | F29: 0.020833333
A30: Salvador Pujol | B30: Raul de Dios | C30: PLK Novelda | D30: 14552 | E30: 0.52083333 | F30: 0.020833333
A31: Salvador Pujol | B31: Raul de Dios | C31: PLK Novelda (DOMINGO) | D31: 14552 | E31: 0.52083333 | F31: 0.041666667
A32: Salvador Pujol | B32: Raul de Dios | C32: PLK Elche Carrefour (DOMINGO) | D32: 15191 | E32: 0.5 | F32: 0.020833333
A33: Salvador Pujol | B33: Raul de Dios | C33: PLK Elche Carrefour (L y J) | D33: 15191 | E33: 0.5 | F33: 0
A34: Salvador Pujol | B34: Pilar Lopez | C34: PLK Jaime 1 (Domingo) | D34: 15156 | E34: 0.45833333 | F34: 0.083333333
A35: Salvador Pujol | B35: Pilar López | C35: PLK Jaime 1 (Lunes a jueves) | D35: 15156 | E35: 0.45833333 | F35: 0.041666667
A36: Salvador Pujol | B36: Pilar López | C36: PLK ALC Finestrat | D36: 14427 | E36: 0.47916667 | F36: 0.0625
A37: Salvador Pujol | B37: Pilar López | C37: PLK Nave Albir | D37: 14989 | E37: 0.5 | F37: 0.020833333
A38: {=IF(_xlfn.XLOOKUP(D38,Aux!C:C,Aux!D:F)=0,"",_xlfn.XLOOKUP(D38,Aux!C:C,Aux!D:F))}
A39: {=IF(_xlfn.XLOOKUP(D39,Aux!C:C,Aux!D:F)=0,"",_xlfn.XLOOKUP(D39,Aux!C:C,Aux!D:F))}
A40: {=IF(_xlfn.XLOOKUP(D40,Aux!C:C,Aux!D:F)=0,"",_xlfn.XLOOKUP(D40,Aux!C:C,Aux!D:F))}
A41: {=IF(_xlfn.XLOOKUP(D41,Aux!C:C,Aux!D:F)=0,"",_xlfn.XLOOKUP(D41,Aux!C:C,Aux!D:F))}
A42: {=IF(_xlfn.XLOOKUP(D42,Aux!C:C,Aux!D:F)=0,"",_xlfn.XLOOKUP(D42,Aux!C:C,Aux!D:F))}
A43: {=IF(_xlfn.XLOOKUP(D43,Aux!C:C,Aux!D:F)=0,"",_xlfn.XLOOKUP(D43,Aux!C:C,Aux!D:F))}
A44: {=IF(_xlfn.XLOOKUP(D44,Aux!C:C,Aux!D:F)=0,"",_xlfn.XLOOKUP(D44,Aux!C:C,Aux!D:F))}
A45: {=IF(_xlfn.XLOOKUP(D45,Aux!C:C,Aux!D:F)=0,"",_xlfn.XLOOKUP(D45,Aux!C:C,Aux!D:F))}
A46: {=IF(_xlfn.XLOOKUP(D46,Aux!C:C,Aux!D:F)=0,"",_xlfn.XLOOKUP(D46,Aux!C:C,Aux!D:F))}
...

Sheet Viernes - Sabado
D1: Inicio horario mañana/continuo | E1: Fin horario mañana/continuo | F1: Inicio horario tarde | G1: Fin horario tarde
B2: Para formatos de HD continuos poner el siguiente formato: | D2: 0.5 | E2: 0.020833333
B3: Para formatos de HD con entreturno poner el siguiente formato: | D3: 0.5 | E3: 0.66666667 | F3: 0.79166667 | G3: 0
D7: Introduce el codigo BK
A8: GA | B8: GZ | C8: RESTAURANTE | D8: RESTAURANTE | E8: Inicio horario mañana/continuo | F8: Fin horario mañana/continuo | G8: Inicio horario tarde | H8: Fin horario tarde
A9: Salvador Pujol | B9: Jose Luis Galiana | C9: PLK Justicia (Viernes-Sabado) | D9: 13884 | E9: 0.5 | F9: 0.083333333
A10: Salvador Pujol | B10: Jose Luis Galiana | C10: PLK Juan de Borbon | D10: 14853 | E10: 0.5 | F10: 0.041666667
A11: Salvador Pujol | B11: Jose Luis Galiana | C11: PLK Aguilas | D11: 15110 | E11: 0.5 | F11: 0.041666667
A12: Salvador Pujol | B12: Jose Luis Galiana | C12: PLK Molina de segura (Viernes) | D12: 14920 | E12: 0.52083333 | F12: 0.041666667
A13: Salvador Pujol | B13: Jose Luis Galiana | C13: PLK Molina de segura (Sabado) | D13: 14920 | E13: 0.52083333 | F13: 0.083333333
A14: Salvador Pujol | B14: Jose Luis Galiana | C14: PLK Traperia | D14: 15223 | E14: 0.5 | F14: 0.041666667
A15: Salvador Pujol | B15: Jose Luis Galiana | C15: PLK Sangonera (Viernes) | D15: 13674 | E15: 0.5 | F15: 0.020833333
A16: Salvador Pujol | B16: Jose Luis Galiana | C16: PLK Sangonera (Sabado) | D16: 13674 | E16: 0.5 | F16: 0.041666667
A17: Salvador Pujol | B17: Jose Luis Galiana | C17: PLK Albacete | D17: 14095 | E17: 0.5 | F17: 0.0625
A18: Salvador Pujol | B18: Vanesa Martinez | C18: Plk Punta Prima | D18: 15989 | E18: 0.45833333 | F18: 0.083333333
A19: Salvador Pujol | B19: Vanesa Martinez | C19: Plk Torrevieja | D19: 15261 | E19: 0.4375 | F19: 0.16666667
A20: Salvador Pujol | B20: Vanesa Martinez | C20: Plk Dos Mares | D20: 14123 | E20: 0.45833333 | F20: 0.020833333
... A28: Salvador Pujol | B28: Pilar Lopez | C28: PLK Nave Albir | D28: 14989 | E28: 0.5 | F28: 0.020833333
A29: {=IF(_xlfn.XLOOKUP(D29,Aux!C:C,Aux!D:F)=0,"",_xlfn.XLOOKUP(D29,Aux!C:C,Aux!D:F))}
A30: {=IF(_xlfn.XLOOKUP(D30,Aux!C:C,Aux!D:F)=0,"",_xlfn.XLOOKUP(D30,Aux!C:C,Aux!D:F))}
A31: {=IF(_xlfn.XLOOKUP(D31,Aux!C:C,Aux!D:F)=0,"",_xlfn.XLOOKUP(D31,Aux!C:C,Aux!D:F))}
A32: {=IF(_xlfn.XLOOKUP(D32,Aux!C:C,Aux!D:F)=0,"",_xlfn.XLOOKUP(D32,Aux!C:C,Aux!D:F))}
A33: {=IF(_xlfn.XLOOKUP(D33,Aux!C:C,Aux!D:F)=0,"",_xlfn.XLOOKUP(D33,Aux!C:C,Aux!D:F))}
A34: {=IF(_xlfn.XLOOKUP(D34,Aux!C:C,Aux!D:F)=0,"",_xlfn.XLOOKUP(D34,Aux!C:C,Aux!D:F))}
A35: {=IF(_xlfn.XLOOKUP(D35,Aux!C:C,Aux!D:F)=0,"",_xlfn.XLOOKUP(D35,Aux!C:C,Aux!D:F))}
A36: {=IF(_xlfn.XLOOKUP(D36,Aux!C:C,Aux!D:F)=0,"",_xlfn.XLOOKUP(D36,Aux!C:C,Aux!D:F))}
A37: {=IF(_xlfn.XLOOKUP(D37,Aux!C:C,Aux!D:F)=0,"",_xlfn.XLOOKUP(D37,Aux!C:C,Aux!D:F))}
A38: {=IF(_xlfn.XLOOKUP(D38,Aux!C:C,Aux!D:F)=0,"",_xlfn.XLOOKUP(D38,Aux!C:C,Aux!D:F))}
A39: {=IF(_xlfn.XLOOKUP(D39,Aux!C:C,Aux!D:F)=0,"",_xlfn.XLOOKUP(D39,Aux!C:C,Aux!D:F))}
A40: {=IF(_xlfn.XLOOKUP(D40,Aux!C:C,Aux!D:F)=0,"",_xlfn.XLOOKUP(D40,Aux!C:C,Aux!D:F))}
... A329: {=IF(_xlfn.XLOOKUP(D329,Aux!C:C,Aux!D:F)=0,"",_xlfn.XLOOKUP(D329,Aux!C:C,Aux!D:F))}

Sheet Aux
A1: 0 | C1: COD REST | D1: RT | E1: GZ | F1: RESTAURANTE
A2: 0.020833333 | C2: 31353 | D2: EVENTOS PT1 | E2: EVENTOS PT2 | F2: BKP FOODTRUCK
A3: 0.041666667 | C3: 15986 | D3: CARLOS GAIOLA | E3: ADAO COSTA | F3: BK AVEIRO CARREFOUR
A4: 0.0625 | C4: 21078 | D4: CARLOS GAIOLA | E4: ADAO COSTA | F4: BK FORUM VISEU
A5: 0.083333333 | C5: 23525 | D5: CARLOS GAIOLA | E5: ADAO COSTA | F5: BK VISEU
A6: 0.10416667 | C6: 26047 | D6: CARLOS GAIOLA | E6: ADAO COSTA | F6: BK ESTARREJA
A7: 0.125 | C7: 26731 | D7: CARLOS GAIOLA | E7: ADAO COSTA | F7: BK ALBERGARIA
A8: 0.14583333 | C8: 26980 | D8: CARLOS GAIOLA | E8: ADAO COSTA | F8: BKP VERDEMILHO
A9: 0.16666667 | C9: 28120 | D9: CARLOS GAIOLA | E9: ADAO COSTA | F9: BKP OLIVEIRA DE AZEMIS
A10: 0.1875 | C10: 31223 | D10: CARLOS GAIOLA | E10: ADAO COSTA | F10: BKP MEALHADA
A11: 0.20833333 | C11: 31996 | D11: CARLOS GAIOLA | E11: ADAO COSTA | F11: BKP AGUEDA
A12: 0.22916667 | C12: 33218 | D12: CARLOS GAIOLA | E12: ADAO COSTA | F12: BKP VALE DE CAMBRA
A13: 0.25 | C13: 26042 | D13: CARLOS GAIOLA | E13: ADILSON RIBEIRO | F13: BK SANTAREM
... A48: 0.97916667 | C48: 26368 | D48: CARLOS GAIOLA | E48: HALIENE RODRIGUES | F48: BK MALVEIRA
C49: 26900 | D49: CARLOS GAIOLA | E49: HALIENE RODRIGUES | F49: BKP VILAFRANCA DE XIRA
C50: 27053 | D50: CARLOS GAIOLA | E50: HALIENE RODRIGUES | F50: BKP ERICEIRA
C51: 27604 | D51: CARLOS GAIOLA | E51: HALIENE RODRIGUES | F51: BKP PORTOALTO
C52: 27605 | D52: CARLOS GAIOLA | E52: HALIENE RODRIGUES | F52: BK LOURINHA
C53: 27910 | D53: CARLOS GAIOLA | E53: HALIENE RODRIGUES | F53: BKP MAFRA
C54: 28948 | D54: CARLOS GAIOLA | E54: HALIENE RODRIGUES | F54: BKP NAZARE
C55: 30286 | D55: CARLOS GAIOLA | E55: HALIENE RODRIGUES | F55: BKP ALCOBACA
C56: 16265 | D56: CARLOS GAIOLA | E56: TIAGO MARQUES | F56: BK TORRES VEDRAS
C57: 17491 | D57: CARLOS GAIOLA | E57: TIAGO MARQUES | F57: BK LEIRIASHOPPING
C58: 21548 | D58: CARLOS GAIOLA | E58: TIAGO MARQUES | F58: BK CALDAS DA RAINHA
C59: 27726 | D59: CARLOS GAIOLA | E59: TIAGO MARQUES | F59: BKP FATIMA
C60: 28699 | D60: CARLOS GAIOLA | E60: TIAGO MARQUES | F60: BK DRIVE TORRES VEDRAS
... C1224: 99929 | D1224: ELENA GARCIA | E1224: JUAN ESTEBAN | F1224: BK SP Parla
